<!DOCTYPE html>
<html lang="en">

<head>
    <meta charset="UTF-8">
    <meta http-equiv="X-UA-Compatible" content="IE=edge">
    <meta name="viewport" content="width=device-width, initial-scale=1.0">
    <title>Errors and Exception</title>
    <meta name="description" content="Errors and Exception">
    <link rel="shortcut icon" href="./python-logo-4k.jpg" type="image/x-icon">
    <link rel="stylesheet" href="https://stackpath.bootstrapcdn.com/bootstrap/4.3.1/css/bootstrap.min.css"
        integrity="sha384-ggOyR0iXCbMQv3Xipma34MD+dH/1fQ784/j6cY/iJTQUOhcWr7x9JvoRxT2MZw1T" crossorigin="anonymous">
    <link rel="stylesheet" type="text/css" href="./static/main.css" />
    <script
        src="https://cdn.jsdelivr.net/gh/google/code-prettify@master/loader/run_prettify.js?autorun=false&amp;lang=llvm&amp;lang=py"></script>
    <script src="./static/html_format.js"></script>


    <script>
        MathJax = {
            tex: { inlineMath: [['$', '$'], ['\\(', '\\)']] }
        };
    </script>
    <script id="MathJax-script" async src="https://cdn.jsdelivr.net/npm/mathjax@3/es5/tex-chtml.js"></script>
</head>

<body>
    <div class="head">
        <a href="./" style="margin: 10%;">Home</a>
        <br>
        <hr>
    </div>

    <div class="container">
        <h1>Errors and Exception</h1>
        
<h2>Error:</h2>
<p>Errors are the problems in a program due to which the program will stop the execution.</p>
<p><a href="https://www.thecrazyprogrammer.com/2014/08/types-of-errors-in-programming.html">Some Common Errors</a></p>
<ol>
<li>Syntax Errors</li>
<li>Run-time Errors</li>
<li>Logical Errors</li>
<li>Latent Errors</li>
</ol>
<p><code>IN [10]</code></p>
<pre><code class="language-python"># list of Errors and exceptions
for i in dir(__builtins__) + dir(__builtin__):
    if &quot;Error&quot; in i:
        print(i)
</code></pre>
<p><strong>stdout</strong></p>
<pre><code class="language-txt">ArithmeticError
AssertionError
AttributeError
BlockingIOError
BrokenPipeError
BufferError
ChildProcessError
ConnectionAbortedError
ConnectionError
ConnectionRefusedError
ConnectionResetError
EOFError
EnvironmentError
FileExistsError
FileNotFoundError
FloatingPointError
IOError
ImportError
IndentationError
IndexError
InterruptedError
IsADirectoryError
KeyError
LookupError
MemoryError
ModuleNotFoundError
NameError
NotADirectoryError
NotImplementedError
OSError
OverflowError
PermissionError
ProcessLookupError
RecursionError
ReferenceError
RuntimeError
SyntaxError
SystemError
TabError
TimeoutError
TypeError
UnboundLocalError
UnicodeDecodeError
UnicodeEncodeError
UnicodeError
UnicodeTranslateError
ValueError
WindowsError
ZeroDivisionError
ArithmeticError
AssertionError
AttributeError
BlockingIOError
BrokenPipeError
BufferError
ChildProcessError
ConnectionAbortedError
ConnectionError
ConnectionRefusedError
ConnectionResetError
EOFError
EnvironmentError
FileExistsError
FileNotFoundError
FloatingPointError
IOError
ImportError
IndentationError
IndexError
InterruptedError
IsADirectoryError
KeyError
LookupError
MemoryError
ModuleNotFoundError
NameError
NotADirectoryError
NotImplementedError
OSError
OverflowError
PermissionError
ProcessLookupError
RecursionError
ReferenceError
RuntimeError
SyntaxError
SystemError
TabError
TimeoutError
TypeError
UnboundLocalError
UnicodeDecodeError
UnicodeEncodeError
UnicodeError
UnicodeTranslateError
ValueError
WindowsError
ZeroDivisionError

</code></pre>
<h2>Exception:</h2>
<p>Exceptions are raised when the some internal events occur which changes the normal flow of the program.</p>
<p><code>IN [9]</code></p>
<pre><code class="language-python"># list of Errors and exceptions
for i in dir(__builtins__) + dir(__builtin__):
    if &quot;Exception&quot; in i:
        print(i)
</code></pre>
<p><strong>stdout</strong></p>
<pre><code class="language-txt">BaseException
Exception
BaseException
Exception

</code></pre>
<h2>Traceback</h2>
<p>The script used below is present <a href="Errors_and_Exception.py">here</a></p>
<p><code>IN [11]</code></p>
<pre><code class="language-python">def a():
    print(&quot;In a&quot;)
    b()
    print(&quot;Back in a&quot;)

def b():
    print(&quot;In b&quot;)
    return 42/0

a() 
</code></pre>
<p><strong>stdout</strong></p>
<pre><code class="language-txt">In a
In b

</code></pre>
<p><strong>Error</strong></p>
<pre><code class="language-err">In a

In b


Traceback (most recent call last):

  File &quot;D:\Programming\Python\Jupyter Notebooks\Python_Programming_Notes\temp.py&quot;, line 10, in &lt;module&gt;

    a() 

  File &quot;D:\Programming\Python\Jupyter Notebooks\Python_Programming_Notes\temp.py&quot;, line 3, in a

    b()

  File &quot;D:\Programming\Python\Jupyter Notebooks\Python_Programming_Notes\temp.py&quot;, line 8, in b

    return 42/0

ZeroDivisionError: division by zero

</code></pre>
<h2>Exception Handling:</h2>
<p>Marking the error-prone zone and controlling what happens when an error / exception is raised is Exception Handling.</p>
<p>In python, Exception Handling can be done using the following:</p>
<ol>
<li><em>try</em> block</li>
<li><em>except</em> block</li>
<li><em>else</em> block</li>
<li><em>finally</em> block</li>
</ol>
<p>Syntax:</p>
<pre><code class="language-python">try:
    # Statements - Critical or Error Prone statements
except ErrorOrExceptionType:
    # Statements - What to do to handle errors
else:
    # Statements - What to do when error is not encountered
finally:
    # Statements - What to do at the end of Exception Handling
</code></pre>
<h3>1. <em>try</em> block:</h3>
<p>The critical operation that might not work as indented or may malfunction is enclosed in the <code>try</code> block. If the statement(s) raise any Error, the execution proceeding in the try block is terminated and moved to <code>except</code> block</p>
<pre><code class="language-python">try:
    # Statement(s) that may cause Errors
</code></pre>
<h3>2. <em>except</em> block</h3>
<p>The <code>except</code> block accepts the error/exception call and works as intended. The except block is used to filter the error that is anticipated.</p>
<pre><code class="language-python">except ErrorOrException:
</code></pre>
<p>The proper way of defining the except block is as above.<br>
Though leaving out the Error name part works fine, it may cause a lot of confusion in many cases and is not recommended</p>
<pre><code class="language-python">except: # Not recommended for use
</code></pre>
<p><code>IN [2]</code></p>
<pre><code class="language-python"># Example
try:
    n = input()
    print(n / 10)
except TypeError:
    print(&quot;Error occurred&quot;)
</code></pre>
<p><strong>stdin</strong></p>
<pre><code class="language-txt"> 123

</code></pre>
<p><strong>stdout</strong></p>
<pre><code class="language-txt">Error occurred

</code></pre>
<p><code>IN [3]</code></p>
<pre><code class="language-python"># Example - not recommended
try:
    n = input()
    print(n / 10)
except: # Don't do it this way
    print(&quot;Error occurred&quot;)
</code></pre>
<p><strong>stdin</strong></p>
<pre><code class="language-txt"> 159

</code></pre>
<p><strong>stdout</strong></p>
<pre><code class="language-txt">Error occurred

</code></pre>
<h3>3. <em>else</em> block</h3>
<p>If there is no error in the code inside <code>try</code> block, the <code>except</code> block is skipped and the <code>else</code> block is executed.</p>
<pre><code class="language-python">else:
    # Statement(s) to run when no error is caused
</code></pre>
<p><code>IN [6]</code></p>
<pre><code class="language-python"># Example
try:
    n = int(input())
    print(10 / n)
except ZeroDivisionError: # Catch when there is division by zero (0)
    print(&quot;Error occurred&quot;)
else:
    print(&quot;Safe&quot;)
</code></pre>
<p><strong>stdin</strong></p>
<pre><code class="language-txt"> 10

</code></pre>
<p><strong>stdout</strong></p>
<pre><code class="language-txt">1.0
Safe

</code></pre>
<h3>4. <em>finally</em> block</h3>
<p>This block is executed at all cases, whether or not an error is encountered inside the <code>try</code> block</p>
<pre><code class="language-python">finally:
    # Statement(s)
</code></pre>
<p><code>IN [1]</code></p>
<pre><code class="language-python"># Example
try:
    n = int(input())
    print(10 / n)
except ZeroDivisionError: # Catch when there is division by zero (0)
    print(&quot;Error occurred&quot;)
else:
    print(&quot;Safe&quot;)
finally:
    print(&quot;End of Program&quot;)
</code></pre>
<p><strong>stdin</strong></p>
<pre><code class="language-txt"> 0

</code></pre>
<p><strong>stdout</strong></p>
<pre><code class="language-txt">Error occurred
End of Program

</code></pre>
<h4><em>as</em> keyword in <em>except</em></h4>
<p>Almost any case of exceptions returns a message about the cause of the error. The above defined method does not get the message for use.  </p>
<p>Using <code>as</code> keyword, the error message can stored in a variable for use inside the <code>except</code> block.</p>
<pre><code class="language-python">except ErrorOrException as err:
    # Statement(s)
</code></pre>
<p><code>IN [2]</code></p>
<pre><code class="language-python"># Example
try:
    n = int(input())
    print(10 / n)
except ZeroDivisionError as e: # Catch when there is division by zero (0)
    print(&quot;Error occurred -&quot;, e) 
    # The message 'division by zero' is stored in e for use in the except block
else:
    print(&quot;Safe&quot;)
finally:
    print(&quot;End of Program&quot;)
</code></pre>
<p><strong>stdin</strong></p>
<pre><code class="language-txt"> 0

</code></pre>
<p><strong>stdout</strong></p>
<pre><code class="language-txt">Error occurred - division by zero
End of Program

</code></pre>
<h2>Intentionally Raising an Exception:</h2>
<p>Python allows you to intentionally raise an exceptio at some cases using <em>raise</em> keyword.</p>
<p>Syntax:</p>
<pre><code class="language-python">raise ExceptionName(&quot;Message&quot;)
</code></pre>
<p>It is important to note that the exception following the <code>raise</code> keyword should either be an instance of a built-in exception or a class inheriting the same (Custom Exception).</p>
<p><code>IN [5]</code></p>
<pre><code class="language-python"># Example - Kelvin to Celsius Conversion
t = int(input(&quot;Enter temperature in Kelvin&quot;))
if t &lt; 0:
    raise ValueError(&quot;The minimum temperature in Kelvin is absolute zero (0)&quot;)
else:
    print(t - 273.15)
</code></pre>
<p><strong>stdin</strong></p>
<pre><code class="language-txt">Enter temperature in Kelvin -1

</code></pre>
<p><strong>Error</strong></p>
<pre><code class="language-err">Enter temperature in Kelvin
Traceback (most recent call last):

  File &quot;D:\Programming\Python\Jupyter Notebooks\Python_Programming_Notes\temp.py&quot;, line 2, in &lt;module&gt;

    t = int(input(&quot;Enter temperature in Kelvin&quot;))

ValueError: invalid literal for int() with base 10: 'Enter temperature in Kelvin -1'

</code></pre>
<h2>Assertion statement:</h2>
<p>An assertion is a sanity-check that you can turn on or turn off for testing your program.</p>
<p>The easiest way to think of an assertion is to liken it to a <code>raise-if</code> statement (or to be more accurate, a raise-if-not statement). An expression or condition is tested, and if the result comes up false, an exception is raised.</p>
<h3><em>assert</em> Statement:</h3>
<p>When it encounters an assert statement, Python evaluates the accompanying expression, which is hopefully true. If the expression is false, Python raises an AssertionError exception.</p>
<pre><code class="language-python">assert expression, &quot;Error message&quot;
</code></pre>
<p>The <code>assert</code> statement is usually enclosed by a <code>try</code> block and the exception is handled. In some cases to terminate the execution, they may not be used.</p>
<p><code>IN [7]</code></p>
<pre><code class="language-python"># Example - Kelvin to Celsius Conversion
t = int(input(&quot;Enter temperature in Kelvin&quot;))
try:
    assert t &gt; 0, &quot;The minimum temperature in Kelvin is absolute zero (0)&quot;
except AssertionError as err:
    print(err)
else:
    print(t - 273.15)
</code></pre>
<p><strong>stdin</strong></p>
<pre><code class="language-txt">Enter temperature in Kelvin -1

</code></pre>
<p><strong>stdout</strong></p>
<pre><code class="language-txt">The minimum temperature in Kelvin is absolute zero (0)

</code></pre>
<h2>Creating custom Errors/Exception from built-ins:</h2>
<p>Python has numerous built-in exceptions that force your program to output an error when something in the program goes wrong.</p>
<p>However, sometimes you may need to create your own custom exceptions that serve your purpose.</p>
<p>In Python, users can define custom exceptions by creating a new class. This exception class has to be derived, either directly or indirectly, from the built-in <code>Exception</code> class. Most of the built-in exceptions are also derived from this class.</p>
<pre><code class="language-python">class My_exception(Exception):
    pass
</code></pre>
<p>To know more about classes, visit <a href="OOPS.html">Object Oriented Programming</a></p>
<p><code>IN [8]</code></p>
<pre><code class="language-python">class My_exception(Exception):
    pass

n = int(input())
if n &gt; 100:
    raise My_exception(&quot;Number is large&quot;)
else:
    print(2 * n)
</code></pre>
<p><strong>stdin</strong></p>
<pre><code class="language-txt"> 101

</code></pre>
<p><strong>Error</strong></p>
<pre><code class="language-err">
Traceback (most recent call last):

  File &quot;D:\Programming\Python\Jupyter Notebooks\Python_Programming_Notes\temp.py&quot;, line 6, in &lt;module&gt;

    raise My_exception(&quot;Number is large&quot;)

__main__.My_exception: Number is large

</code></pre>
    </div>


</body>

</html>